Workbook

Sheet Inputs
A1: Email Input
A4: Field | B4: Value
A5: Subject | B5: Urgent: Payment Required Immediately
A6: Body | B6: Dear Customer, Your account shows an overdue balance. To avoid service suspension, please make payment within 12 hours. Click here to settle your account: bank@official.bank.com Failure to comply will result in permanent account closure. Sincerely, Billing Department
A8: Formula Name | B8: Formula Display | C8: Meaning
A9: Bayes theorem | B9: General: P(class | features) = [P(features | class) * P(class)] / P(features) Fraud: P(fraud | features) = [P(features | fraud) * P(fraud)] / P(features) Injection: P(injection | features) = [P(features | injection) * P(injection)] / P(features) Safe: P(safe | features) = [P(features | safe) * P(safe)] / P(features) | C9: Posterior probability after observing features X.
A10: Naive Bayes likelihood | B10: P(features | fraud) = product_i P(token_i | fraud) P(features | injection) = product_i P(token_i | injection) P(features | safe) = product_i P(token_i | safe) | C10: The project uses log form for numerical stability.
A11: Laplace smoothing | B11: log_score(fraud) = ln(P(fraud)) + sum_i count(token_i) * ln(P(token_i | fraud)) log_score(injection) = ln(P(injection)) + sum_i count(token_i) * ln(P(token_i | injection)) log_score(safe) = ln(P(safe)) + sum_i count(token_i) * ln(P(token_i | safe)) | C11: Prevents zero probabilities for unseen features.
A12: Log scoring | B12: P(token | fraud) = (freq(token,fraud)+alpha)/(token_total(fraud)+alpha*|V|) P(token | injection) = (freq(token,injection)+alpha)/(token_total(injection)+alpha*|V|) P(token | safe) = (freq(token,safe)+alpha)/(token_total(safe)+alpha*|V|) | C12: Raw scores used to choose the predicted label.
A13: Temperature softmax | B13: logit(fraud)=log_score(fraud)/token_count logit(injection)=log_score(injection)/token_count logit(safe)=log_score(safe)/token_count | C13: Final UI probabilities shown by the project.

Sheet Model Parameters
A1: Model Parameters From Dataset
A4: Parameter | B4: Fraud | C4: Injection | D4: Safe | E4: Formula / Meaning
A5: Class document count | B5: 3333 | C5: 3333 | D5: 3334 | E5: class_count(C_k)
A6: Total documents | B6: 10000 | C6: 10000 | D6: 10000 | E6: sum of all class document counts
A7: Class prior P(C_k) | B7: =B5/B6 -> 0.3333 | C7: =C5/C6 -> 0.3333 | D7: =D5/D6 -> 0.3334 | E7: P(fraud)=fraud_count/total_docs; P(injection)=injection_count/total_docs; P(safe)=safe_count/total_docs
A8: ln prior | B8: =LN(B7) -> -1.0987123 | C8: =LN(C7) -> -1.0987123 | D8: =LN(D7) -> -1.0984123 | E8: ln(P(fraud)), ln(P(injection)), ln(P(safe))
A9: Class token total | B9: 1168629 | C9: 879465 | D9: 219954 | E9: sum of feature counts in each class
A10: Vocabulary size |V| | B10: 6874 | C10: 6874 | D10: 6874 | E10: unique training features
A11: Laplace alpha | B11: 1 | C11: 1 | D11: 1 | E11: alpha
A12: Posterior temperature T | B12: 0.2 | C12: 0.2 | D12: 0.2 | E12: temperature used by softmax
A13: Keyword weight | B13: 10 | C13: 10 | D13: 10 | E13: fraud/injection keyword synthetic feature weight

Sheet Keyword Influence
A1: Keyword Influence
A4: Keyword | B4: Category | C4: Matched? | D4: Adds __fraud_kw__ | E4: Adds __injection_kw__ | F4: Adds __malicious_signal__ | G4: Formula shown
A5: account | B5: fraud | C5: =--ISNUMBER(SEARCH(A5,LOWER(Inputs!$B$5&" "&Inputs!$B$6))) -> TRUE | D5: 2 | E5: =IF(AND(B5="injection",C5=1),'Model Parameters'!$C$13,0) -> 0 | F5: 2 | G5: matched? = ISNUMBER(SEARCH(keyword, subject & body)); synthetic_count += keyword_weight
A6: account closure | B6: fraud | C6: =--ISNUMBER(SEARCH(A6,LOWER(Inputs!$B$5&" "&Inputs!$B$6))) -> TRUE | D6: 2 | E6: =IF(AND(B6="injection",C6=1),'Model Parameters'!$C$13,0) -> 0 | F6: 2 | G6: matched? = ISNUMBER(SEARCH(keyword, subject & body)); synthetic_count += keyword_weight
A7: account locked | B7: fraud | C7: =--ISNUMBER(SEARCH(A7,LOWER(Inputs!$B$5&" "&Inputs!$B$6))) -> FALSE | D7: =IF(AND(B7="fraud",C7=1),'Model Parameters'!$B$13,0) -> 0 | E7: =IF(AND(B7="injection",C7=1),'Model Parameters'!$C$13,0) -> 0 | F7: =IF(C7=1,IF(B7="fraud",'Model Parameters'!$B$13,'Model Parameters'!$C$13),0) -> 0 | G7: matched? = ISNUMBER(SEARCH(keyword, subject & body)); synthetic_count += keyword_weight
A8: account verification | B8: fraud | C8: =--ISNUMBER(SEARCH(A8,LOWER(Inputs!$B$5&" "&Inputs!$B$6))) -> FALSE | D8: =IF(AND(B8="fraud",C8=1),'Model Parameters'!$B$13,0) -> 0 | E8: =IF(AND(B8="injection",C8=1),'Model Parameters'!$C$13,0) -> 0 | F8: =IF(C8=1,IF(B8="fraud",'Model Parameters'!$B$13,'Model Parameters'!$C$13),0) -> 0 | G8: matched? = ISNUMBER(SEARCH(keyword, subject & body)); synthetic_count += keyword_weight
A9: act now | B9: fraud | C9: =--ISNUMBER(SEARCH(A9,LOWER(Inputs!$B$5&" "&Inputs!$B$6))) -> FALSE | D9: =IF(AND(B9="fraud",C9=1),'Model Parameters'!$B$13,0) -> 0 | E9: =IF(AND(B9="injection",C9=1),'Model Parameters'!$C$13,0) -> 0 | F9: =IF(C9=1,IF(B9="fraud",'Model Parameters'!$B$13,'Model Parameters'!$C$13),0) -> 0 | G9: matched? = ISNUMBER(SEARCH(keyword, subject & body)); synthetic_count += keyword_weight
A10: action | B10: fraud | C10: =--ISNUMBER(SEARCH(A10,LOWER(Inputs!$B$5&" "&Inputs!$B$6))) -> FALSE | D10: =IF(AND(B10="fraud",C10=1),'Model Parameters'!$B$13,0) -> 0 | E10: =IF(AND(B10="injection",C10=1),'Model Parameters'!$C$13,0) -> 0 | F10: =IF(C10=1,IF(B10="fraud",'Model Parameters'!$B$13,'Model Parameters'!$C$13),0) -> 0 | G10: matched? = ISNUMBER(SEARCH(keyword, subject & body)); synthetic_count += keyword_weight
A11: activity | B11: fraud | C11: =--ISNUMBER(SEARCH(A11,LOWER(Inputs!$B$5&" "&Inputs!$B$6))) -> FALSE | D11: =IF(AND(B11="fraud",C11=1),'Model Parameters'!$B$13,0) -> 0 | E11: =IF(AND(B11="injection",C11=1),'Model Parameters'!$C$13,0) -> 0 | F11: =IF(C11=1,IF(B11="fraud",'Model Parameters'!$B$13,'Model Parameters'!$C$13),0) -> 0 | G11: matched? = ISNUMBER(SEARCH(keyword, subject & body)); synthetic_count += keyword_weight
A12: alert | B12: fraud | C12: =--ISNUMBER(SEARCH(A12,LOWER(Inputs!$B$5&" "&Inputs!$B$6))) -> FALSE | D12: =IF(AND(B12="fraud",C12=1),'Model Parameters'!$B$13,0) -> 0 | E12: =IF(AND(B12="injection",C12=1),'Model Parameters'!$C$13,0) -> 0 | F12: =IF(C12=1,IF(B12="fraud",'Model Parameters'!$B$13,'Model Parameters'!$C$13),0) -> 0 | G12: matched? = ISNUMBER(SEARCH(keyword, subject & body)); synthetic_count += keyword_weight
A13: amazon | B13: fraud | C13: =--ISNUMBER(SEARCH(A13,LOWER(Inputs!$B$5&" "&Inputs!$B$6))) -> FALSE | D13: =IF(AND(B13="fraud",C13=1),'Model Parameters'!$B$13,0) -> 0 | E13: =IF(AND(B13="injection",C13=1),'Model Parameters'!$C$13,0) -> 0 | F13: =IF(C13=1,IF(B13="fraud",'Model Parameters'!$B$13,'Model Parameters'!$C$13),0) -> 0 | G13: matched? = ISNUMBER(SEARCH(keyword, subject & body)); synthetic_count += keyword_weight
A14: apple | B14: fraud | C14: =--ISNUMBER(SEARCH(A14,LOWER(Inputs!$B$5&" "&Inputs!$B$6))) -> FALSE | D14: =IF(AND(B14="fraud",C14=1),'Model Parameters'!$B$13,0) -> 0 | E14: =IF(AND(B14="injection",C14=1),'Model Parameters'!$C$13,0) -> 0 | F14: =IF(C14=1,IF(B14="fraud",'Model Parameters'!$B$13,'Model Parameters'!$C$13),0) -> 0 | G14: matched? = ISNUMBER(SEARCH(keyword, subject & body)); synthetic_count += keyword_weight
A15: bank | B15: fraud | C15: =--ISNUMBER(SEARCH(A15,LOWER(Inputs!$B$5&" "&Inputs!$B$6))) -> TRUE | D15: 2 | E15: =IF(AND(B15="injection",C15=1),'Model Parameters'!$C$13,0) -> 0 | F15: 2 | G15: matched? = ISNUMBER(SEARCH(keyword, subject & body)); synthetic_count += keyword_weight
A16: bank details | B16: fraud | C16: =--ISNUMBER(SEARCH(A16,LOWER(Inputs!$B$5&" "&Inputs!$B$6))) -> FALSE | D16: =IF(AND(B16="fraud",C16=1),'Model Parameters'!$B$13,0) -> 0 | E16: =IF(AND(B16="injection",C16=1),'Model Parameters'!$C$13,0) -> 0 | F16: =IF(C16=1,IF(B16="fraud",'Model Parameters'!$B$13,'Model Parameters'!$C$13),0) -> 0 | G16: matched? = ISNUMBER(SEARCH(keyword, subject & body)); synthetic_count += keyword_weight
A17: billing | B17: fraud | C17: =--ISNUMBER(SEARCH(A17,LOWER(Inputs!$B$5&" "&Inputs!$B$6))) -> TRUE | D17: 2 | E17: =IF(AND(B17="injection",C17=1),'Model Parameters'!$C$13,0) -> 0 | F17: 2 | G17: matched? = ISNUMBER(SEARCH(keyword, subject & body)); synthetic_count += keyword_weight
A18: card declined | B18: fraud | C18: =--ISNUMBER(SEARCH(A18,LOWER(Inputs!$B$5&" "&Inputs!$B$6))) -> FALSE | D18: =IF(AND(B18="fraud",C18=1),'Model Parameters'!$B$13,0) -> 0 | E18: =IF(AND(B18="injection",C18=1),'Model Parameters'!$C$13,0) -> 0 | F18: =IF(C18=1,IF(B18="fraud",'Model Parameters'!$B$13,'Model Parameters'!$C$13),0) -> 0 | G18: matched? = ISNUMBER(SEARCH(keyword, subject & body)); synthetic_count += keyword_weight
A19: cash prize | B19: fraud | C19: =--ISNUMBER(SEARCH(A19,LOWER(Inputs!$B$5&" "&Inputs!$B$6))) -> FALSE | D19: =IF(AND(B19="fraud",C19=1),'Model Parameters'!$B$13,0) -> 0 | E19: =IF(AND(B19="injection",C19=1),'Model Parameters'!$C$13,0) -> 0 | F19: =IF(C19=1,IF(B19="fraud",'Model Parameters'!$B$13,'Model Parameters'!$C$13),0) -> 0 | G19: matched? = ISNUMBER(SEARCH(keyword, subject & body)); synthetic_count += keyword_weight
A20: claim | B20: fraud | C20: =--ISNUMBER(SEARCH(A20,LOWER(Inputs!$B$5&" "&Inputs!$B$6))) -> FALSE | D20: =IF(AND(B20="fraud",C20=1),'Model Parameters'!$B$13,0) -> 0 | E20: =IF(AND(B20="injection",C20=1),'Model Parameters'!$C$13,0) -> 0 | F20: =IF(C20=1,IF(B20="fraud",'Model Parameters'!$B$13,'Model Parameters'!$C$13),0) -> 0 | G20: matched? = ISNUMBER(SEARCH(keyword, subject & body)); synthetic_count += keyword_weight
A21: claim reward | B21: fraud | C21: =--ISNUMBER(SEARCH(A21,LOWER(Inputs!$B$5&" "&Inputs!$B$6))) -> FALSE | D21: =IF(AND(B21="fraud",C21=1),'Model Parameters'!$B$13,0) -> 0 | E21: =IF(AND(B21="injection",C21=1),'Model Parameters'!$C$13,0) -> 0 | F21: =IF(C21=1,IF(B21="fraud",'Model Parameters'!$B$13,'Model Parameters'!$C$13),0) -> 0 | G21: matched? = ISNUMBER(SEARCH(keyword, subject & body)); synthetic_count += keyword_weight
A22: click | B22: fraud | C22: =--ISNUMBER(SEARCH(A22,LOWER(Inputs!$B$5&" "&Inputs!$B$6))) -> TRUE | D22: 2 | E22: =IF(AND(B22="injection",C22=1),'Model Parameters'!$C$13,0) -> 0 | F22: 2 | G22: matched? = ISNUMBER(SEARCH(keyword, subject & body)); synthetic_count += keyword_weight
A23: click here | B23: fraud | C23: =--ISNUMBER(SEARCH(A23,LOWER(Inputs!$B$5&" "&Inputs!$B$6))) -> TRUE | D23: 2 | E23: =IF(AND(B23="injection",C23=1),'Model Parameters'!$C$13,0) -> 0 | F23: 2 | G23: matched? = ISNUMBER(SEARCH(keyword, subject & body)); synthetic_count += keyword_weight
A24: confirm | B24: fraud | C24: =--ISNUMBER(SEARCH(A24,LOWER(Inputs!$B$5&" "&Inputs!$B$6))) -> FALSE | D24: =IF(AND(B24="fraud",C24=1),'Model Parameters'!$B$13,0) -> 0 | E24: =IF(AND(B24="injection",C24=1),'Model Parameters'!$C$13,0) -> 0 | F24: =IF(C24=1,IF(B24="fraud",'Model Parameters'!$B$13,'Model Parameters'!$C$13),0) -> 0 | G24: matched? = ISNUMBER(SEARCH(keyword, subject & body)); synthetic_count += keyword_weight
A25: confirm account | B25: fraud | C25: =--ISNUMBER(SEARCH(A25,LOWER(Inputs!$B$5&" "&Inputs!$B$6))) -> FALSE | D25: =IF(AND(B25="fraud",C25=1),'Model Parameters'!$B$13,0) -> 0 | E25: =IF(AND(B25="injection",C25=1),'Model Parameters'!$C$13,0) -> 0 | F25: =IF(C25=1,IF(B25="fraud",'Model Parameters'!$B$13,'Model Parameters'!$C$13),0) -> 0 | G25: matched? = ISNUMBER(SEARCH(keyword, subject & body)); synthetic_count += keyword_weight
A26: confirm identity | B26: fraud | C26: =--ISNUMBER(SEARCH(A26,LOWER(Inputs!$B$5&" "&Inputs!$B$6))) -> FALSE | D26: =IF(AND(B26="fraud",C26=1),'Model Parameters'!$B$13,0) -> 0 | E26: =IF(AND(B26="injection",C26=1),'Model Parameters'!$C$13,0) -> 0 | F26: =IF(C26=1,IF(B26="fraud",'Model Parameters'!$B$13,'Model Parameters'!$C$13),0) -> 0 | G26: matched? = ISNUMBER(SEARCH(keyword, subject & body)); synthetic_count += keyword_weight
A27: confirm payment | B27: fraud | C27: =--ISNUMBER(SEARCH(A27,LOWER(Inputs!$B$5&" "&Inputs!$B$6))) -> FALSE | D27: =IF(AND(B27="fraud",C27=1),'Model Parameters'!$B$13,0) -> 0 | E27: =IF(AND(B27="injection",C27=1),'Model Parameters'!$C$13,0) -> 0 | F27: =IF(C27=1,IF(B27="fraud",'Model Parameters'!$B$13,'Model Parameters'!$C$13),0) -> 0 | G27: matched? = ISNUMBER(SEARCH(keyword, subject & body)); synthetic_count += keyword_weight
A28: congratulations | B28: fraud | C28: =--ISNUMBER(SEARCH(A28,LOWER(Inputs!$B$5&" "&Inputs!$B$6))) -> FALSE | D28: =IF(AND(B28="fraud",C28=1),'Model Parameters'!$B$13,0) -> 0 | E28: =IF(AND(B28="injection",C28=1),'Model Parameters'!$C$13,0) -> 0 | F28: =IF(C28=1,IF(B28="fraud",'Model Parameters'!$B$13,'Model Parameters'!$C$13),0) -> 0 | G28: matched? = ISNUMBER(SEARCH(keyword, subject & body)); synthetic_count += keyword_weight
A29: credential | B29: fraud | C29: =--ISNUMBER(SEARCH(A29,LOWER(Inputs!$B$5&" "&Inputs!$B$6))) -> FALSE | D29: =IF(AND(B29="fraud",C29=1),'Model Parameters'!$B$13,0) -> 0 | E29: =IF(AND(B29="injection",C29=1),'Model Parameters'!$C$13,0) -> 0 | F29: =IF(C29=1,IF(B29="fraud",'Model Parameters'!$B$13,'Model Parameters'!$C$13),0) -> 0 | G29: matched? = ISNUMBER(SEARCH(keyword, subject & body)); synthetic_count += keyword_weight
A30: crypto | B30: fraud | C30: =--ISNUMBER(SEARCH(A30,LOWER(Inputs!$B$5&" "&Inputs!$B$6))) -> FALSE | D30: =IF(AND(B30="fraud",C30=1),'Model Parameters'!$B$13,0) -> 0 | E30: =IF(AND(B30="injection",C30=1),'Model Parameters'!$C$13,0) -> 0 | F30: =IF(C30=1,IF(B30="fraud",'Model Parameters'!$B$13,'Model Parameters'!$C$13),0) -> 0 | G30: matched? = ISNUMBER(SEARCH(keyword, subject & body)); synthetic_count += keyword_weight
A31: customs fee | B31: fraud | C31: =--ISNUMBER(SEARCH(A31,LOWER(Inputs!$B$5&" "&Inputs!$B$6))) -> FALSE | D31: =IF(AND(B31="fraud",C31=1),'Model Parameters'!$B$13,0) -> 0 | E31: =IF(AND(B31="injection",C31=1),'Model Parameters'!$C$13,0) -> 0 | F31: =IF(C31=1,IF(B31="fraud",'Model Parameters'!$B$13,'Model Parameters'!$C$13),0) -> 0 | G31: matched? = ISNUMBER(SEARCH(keyword, subject & body)); synthetic_count += keyword_weight
A32: deactivate account | B32: fraud | C32: =--ISNUMBER(SEARCH(A32,LOWER(Inputs!$B$5&" "&Inputs!$B$6))) -> FALSE | D32: =IF(AND(B32="fraud",C32=1),'Model Parameters'!$B$13,0) -> 0 | E32: =IF(AND(B32="injection",C32=1),'Model Parameters'!$C$13,0) -> 0 | F32: =IF(C32=1,IF(B32="fraud",'Model Parameters'!$B$13,'Model Parameters'!$C$13),0) -> 0 | G32: matched? = ISNUMBER(SEARCH(keyword, subject & body)); synthetic_count += keyword_weight
A33: deactivation | B33: fraud | C33: =--ISNUMBER(SEARCH(A33,LOWER(Inputs!$B$5&" "&Inputs!$B$6))) -> FALSE | D33: =IF(AND(B33="fraud",C33=1),'Model Parameters'!$B$13,0) -> 0 | E33: =IF(AND(B33="injection",C33=1),'Model Parameters'!$C$13,0) -> 0 | F33: =IF(C33=1,IF(B33="fraud",'Model Parameters'!$B$13,'Model Parameters'!$C$13),0) -> 0 | G33: matched? = ISNUMBER(SEARCH(keyword, subject & body)); synthetic_count += keyword_weight
A34: expire | B34: fraud | C34: =--ISNUMBER(SEARCH(A34,LOWER(Inputs!$B$5&" "&Inputs!$B$6))) -> FALSE | D34: =IF(AND(B34="fraud",C34=1),'Model Parameters'!$B$13,0) -> 0 | E34: =IF(AND(B34="injection",C34=1),'Model Parameters'!$C$13,0) -> 0 | F34: =IF(C34=1,IF(B34="fraud",'Model Parameters'!$B$13,'Model Parameters'!$C$13),0) -> 0 | G34: matched? = ISNUMBER(SEARCH(keyword, subject & body)); synthetic_count += keyword_weight
A35: failure to comply | B35: fraud | C35: =--ISNUMBER(SEARCH(A35,LOWER(Inputs!$B$5&" "&Inputs!$B$6))) -> TRUE | D35: 2 | E35: =IF(AND(B35="injection",C35=1),'Model Parameters'!$C$13,0) -> 0 | F35: 2 | G35: matched? = ISNUMBER(SEARCH(keyword, subject & body)); synthetic_count += keyword_weight
A36: final notice | B36: fraud | C36: =--ISNUMBER(SEARCH(A36,LOWER(Inputs!$B$5&" "&Inputs!$B$6))) -> FALSE | D36: =IF(AND(B36="fraud",C36=1),'Model Parameters'!$B$13,0) -> 0 | E36: =IF(AND(B36="injection",C36=1),'Model Parameters'!$C$13,0) -> 0 | F36: =IF(C36=1,IF(B36="fraud",'Model Parameters'!$B$13,'Model Parameters'!$C$13),0) -> 0 | G36: matched? = ISNUMBER(SEARCH(keyword, subject & body)); synthetic_count += keyword_weight
A37: final warning | B37: fraud | C37: =--ISNUMBER(SEARCH(A37,LOWER(Inputs!$B$5&" "&Inputs!$B$6))) -> FALSE | D37: =IF(AND(B37="fraud",C37=1),'Model Parameters'!$B$13,0) -> 0 | E37: =IF(AND(B37="injection",C37=1),'Model Parameters'!$C$13,0) -> 0 | F37: =IF(C37=1,IF(B37="fraud",'Model Parameters'!$B$13,'Model Parameters'!$C$13),0) -> 0 | G37: matched? = ISNUMBER(SEARCH(keyword, subject & body)); synthetic_count += keyword_weight
A38: fraud alert | B38: fraud | C38: =--ISNUMBER(SEARCH(A38,LOWER(Inputs!$B$5&" "&Inputs!$B$6))) -> FALSE | D38: =IF(AND(B38="fraud",C38=1),'Model Parameters'!$B$13,0) -> 0 | E38: =IF(AND(B38="injection",C38=1),'Model Parameters'!$C$13,0) -> 0 | F38: =IF(C38=1,IF(B38="fraud",'Model Parameters'!$B$13,'Model Parameters'!$C$13),0) -> 0 | G38: matched? = ISNUMBER(SEARCH(keyword, subject & body)); synthetic_count += keyword_weight
A39: gift card | B39: fraud | C39: =--ISNUMBER(SEARCH(A39,LOWER(Inputs!$B$5&" "&Inputs!$B$6))) -> FALSE | D39: =IF(AND(B39="fraud",C39=1),'Model Parameters'!$B$13,0) -> 0 | E39: =IF(AND(B39="injection",C39=1),'Model Parameters'!$C$13,0) -> 0 | F39: =IF(C39=1,IF(B39="fraud",'Model Parameters'!$B$13,'Model Parameters'!$C$13),0) -> 0 | G39: matched? = ISNUMBER(SEARCH(keyword, subject & body)); synthetic_count += keyword_weight
A40: identity | B40: fraud | C40: =--ISNUMBER(SEARCH(A40,LOWER(Inputs!$B$5&" "&Inputs!$B$6))) -> FALSE | D40: =IF(AND(B40="fraud",C40=1),'Model Parameters'!$B$13,0) -> 0 | E40: =IF(AND(B40="injection",C40=1),'Model Parameters'!$C$13,0) -> 0 | F40: =IF(C40=1,IF(B40="fraud",'Model Parameters'!$B$13,'Model Parameters'!$C$13),0) -> 0 | G40: matched? = ISNUMBER(SEARCH(keyword, subject & body)); synthetic_count += keyword_weight
A41: identity confirmation | B41: fraud | C41: =--ISNUMBER(SEARCH(A41,LOWER(Inputs!$B$5&" "&Inputs!$B$6))) -> FALSE | D41: =IF(AND(B41="fraud",C41=1),'Model Parameters'!$B$13,0) -> 0 | E41: =IF(AND(B41="injection",C41=1),'Model Parameters'!$C$13,0) -> 0 | F41: =IF(C41=1,IF(B41="fraud",'Model Parameters'!$B$13,'Model Parameters'!$C$13),0) -> 0 | G41: matched? = ISNUMBER(SEARCH(keyword, subject & body)); synthetic_count += keyword_weight
A42: immediate | B42: fraud | C42: =--ISNUMBER(SEARCH(A42,LOWER(Inputs!$B$5&" "&Inputs!$B$6))) -> TRUE | D42: 2 | E42: =IF(AND(B42="injection",C42=1),'Model Parameters'!$C$13,0) -> 0 | F42: 2 | G42: matched? = ISNUMBER(SEARCH(keyword, subject & body)); synthetic_count += keyword_weight
...

Sheet Token Table
A1: Token Table With Excel Formulas
A3: Formula shown: P(token | fraud/injection/safe) = (training frequency in that class + alpha) / (class token total + alpha*|V|). Contribution = observed_count * LN(P(token | fraud/injection/safe)).
A6: Token / feature | B6: Observed count | C6: Fraud freq | D6: Fraud P | E6: Fraud log contribution | F6: Injection freq | G6: Injection P | H6: Injection log contribution | I6: Safe freq | J6: Safe P | K6: Safe log contribution
A7: __fraud_kw__ | B7: ='Keyword Influence'!D197 -> 32 | C7: 481750 | D7: =(C7+'Model Parameters'!$B$11)/('Model Parameters'!$B$9+'Model Parameters'!$B$11*'Model Parameters'!$B$10) -> 0.40982541 | E7: =B7*LN(D7) -> -28.544769 | F7: 35240 | G7: =(F7+'Model Parameters'!$C$11)/('Model Parameters'!$C$9+'Model Parameters'!$C$11*'Model Parameters'!$C$10) -> 0.039760182 | H7: =B7*LN(G7) -> -103.19646 | I7: 44550 | J7: =(I7+'Model Parameters'!$D$11)/('Model Parameters'!$D$9+'Model Parameters'!$D$11*'Model Parameters'!$D$10) -> 0.19640873 | K7: =B7*LN(J7) -> -52.081837
A8: __malicious_signal__ | B8: ='Keyword Influence'!F197 -> 32 | C8: 486220 | D8: =(C8+'Model Parameters'!$B$11)/('Model Parameters'!$B$9+'Model Parameters'!$B$11*'Model Parameters'!$B$10) -> 0.41362804 | E8: =B8*LN(D8) -> -28.249221 | F8: 345670 | G8: =(F8+'Model Parameters'!$C$11)/('Model Parameters'!$C$9+'Model Parameters'!$C$11*'Model Parameters'!$C$10) -> 0.38999863 | H8: =B8*LN(G8) -> -30.131585 | I8: 44550 | J8: =(I8+'Model Parameters'!$D$11)/('Model Parameters'!$D$9+'Model Parameters'!$D$11*'Model Parameters'!$D$10) -> 0.19640873 | K8: =B8*LN(J8) -> -52.081837
A9: account | B9: 3 | C9: 5621 | D9: =(C9+'Model Parameters'!$B$11)/('Model Parameters'!$B$9+'Model Parameters'!$B$11*'Model Parameters'!$B$10) -> 0.0047826335 | E9: =B9*LN(D9) -> -16.028292 | F9: 39 | G9: =(F9+'Model Parameters'!$C$11)/('Model Parameters'!$C$9+'Model Parameters'!$C$11*'Model Parameters'!$C$10) -> 4.5129459e-05 | H9: =B9*LN(G9) -> -30.017926 | I9: 1540 | J9: =(I9+'Model Parameters'!$D$11)/('Model Parameters'!$D$9+'Model Parameters'!$D$11*'Model Parameters'!$D$10) -> 0.0067936939 | K9: =B9*LN(J9) -> -14.975281
A10: payment | B10: 3 | C10: 3577 | D10: =(C10+'Model Parameters'!$B$11)/('Model Parameters'!$B$9+'Model Parameters'!$B$11*'Model Parameters'!$B$10) -> 0.0030438034 | E10: =B10*LN(D10) -> -17.383942 | F10: 29 | G10: =(F10+'Model Parameters'!$C$11)/('Model Parameters'!$C$9+'Model Parameters'!$C$11*'Model Parameters'!$C$10) -> 3.3847095e-05 | H10: =B10*LN(G10) -> -30.880972 | I10: 1 | J10: =(I10+'Model Parameters'!$D$11)/('Model Parameters'!$D$9+'Model Parameters'!$D$11*'Model Parameters'!$D$10) -> 8.8172536e-06 | K10: =B10*LN(J10) -> -34.9164
A11: bank | B11: 2 | C11: 477 | D11: =(C11+'Model Parameters'!$B$11)/('Model Parameters'!$B$9+'Model Parameters'!$B$11*'Model Parameters'!$B$10) -> 0.00040663444 | E11: =B11*LN(D11) -> -15.615192 | F11: 5 | G11: =(F11+'Model Parameters'!$C$11)/('Model Parameters'!$C$9+'Model Parameters'!$C$11*'Model Parameters'!$C$10) -> 6.7694189e-06 | H11: =B11*LN(G11) -> -23.806191 | I11: 1 | J11: =(I11+'Model Parameters'!$D$11)/('Model Parameters'!$D$9+'Model Parameters'!$D$11*'Model Parameters'!$D$10) -> 8.8172536e-06 | K11: =B11*LN(J11) -> -23.2776
A12: immediately | B12: 2 | C12: 834 | D12: =(C12+'Model Parameters'!$B$11)/('Model Parameters'!$B$9+'Model Parameters'!$B$11*'Model Parameters'!$B$10) -> 0.00071033421 | E12: =B12*LN(D12) -> -14.49955 | F12: 415 | G12: =(F12+'Model Parameters'!$C$11)/('Model Parameters'!$C$9+'Model Parameters'!$C$11*'Model Parameters'!$C$10) -> 0.00046934638 | H12: =B12*LN(G12) -> -15.328339 | I12: 0 | J12: =(I12+'Model Parameters'!$D$11)/('Model Parameters'!$D$9+'Model Parameters'!$D$11*'Model Parameters'!$D$10) -> 4.4086268e-06 | K12: =B12*LN(J12) -> -24.663895
A13: payment_required | B13: 2 | C13: 1384 | D13: =(C13+'Model Parameters'!$B$11)/('Model Parameters'!$B$9+'Model Parameters'!$B$11*'Model Parameters'!$B$10) -> 0.001178219 | E13: =B13*LN(D13) -> -13.487503 | F13: 0 | G13: =(F13+'Model Parameters'!$C$11)/('Model Parameters'!$C$9+'Model Parameters'!$C$11*'Model Parameters'!$C$10) -> 1.1282365e-06 | H13: =B13*LN(G13) -> -27.38971 | I13: 0 | J13: =(I13+'Model Parameters'!$D$11)/('Model Parameters'!$D$9+'Model Parameters'!$D$11*'Model Parameters'!$D$10) -> 4.4086268e-06 | K13: =B13*LN(J13) -> -24.663895
A14: required | B14: 2 | C14: 1881 | D14: =(C14+'Model Parameters'!$B$11)/('Model Parameters'!$B$9+'Model Parameters'!$B$11*'Model Parameters'!$B$10) -> 0.0016010168 | E14: =B14*LN(D14) -> -12.874233 | F14: 18 | G14: =(F14+'Model Parameters'!$C$11)/('Model Parameters'!$C$9+'Model Parameters'!$C$11*'Model Parameters'!$C$10) -> 2.1436493e-05 | H14: =B14*LN(G14) -> -21.500832 | I14: 20 | J14: =(I14+'Model Parameters'!$D$11)/('Model Parameters'!$D$9+'Model Parameters'!$D$11*'Model Parameters'!$D$10) -> 9.2581163e-05 | K14: =B14*LN(J14) -> -18.57485
A15: required_immediately | B15: 2 | C15: 453 | D15: =(C15+'Model Parameters'!$B$11)/('Model Parameters'!$B$9+'Model Parameters'!$B$11*'Model Parameters'!$B$10) -> 0.00038621764 | E15: =B15*LN(D15) -> -15.718219 | F15: 0 | G15: =(F15+'Model Parameters'!$C$11)/('Model Parameters'!$C$9+'Model Parameters'!$C$11*'Model Parameters'!$C$10) -> 1.1282365e-06 | H15: =B15*LN(G15) -> -27.38971 | I15: 0 | J15: =(I15+'Model Parameters'!$D$11)/('Model Parameters'!$D$9+'Model Parameters'!$D$11*'Model Parameters'!$D$10) -> 4.4086268e-06 | K15: =B15*LN(J15) -> -24.663895
A16: urgent | B16: 2 | C16: 499 | D16: =(C16+'Model Parameters'!$B$11)/('Model Parameters'!$B$9+'Model Parameters'!$B$11*'Model Parameters'!$B$10) -> 0.00042534983 | E16: =B16*LN(D16) -> -15.525197 | F16: 5 | G16: =(F16+'Model Parameters'!$C$11)/('Model Parameters'!$C$9+'Model Parameters'!$C$11*'Model Parameters'!$C$10) -> 6.7694189e-06 | H16: =B16*LN(G16) -> -23.806191 | I16: 0 | J16: =(I16+'Model Parameters'!$D$11)/('Model Parameters'!$D$9+'Model Parameters'!$D$11*'Model Parameters'!$D$10) -> 4.4086268e-06 | K16: =B16*LN(J16) -> -24.663895
A17: urgent_payment | B17: 2 | C17: 454 | D17: =(C17+'Model Parameters'!$B$11)/('Model Parameters'!$B$9+'Model Parameters'!$B$11*'Model Parameters'!$B$10) -> 0.00038706834 | E17: =B17*LN(D17) -> -15.713819 | F17: 0 | G17: =(F17+'Model Parameters'!$C$11)/('Model Parameters'!$C$9+'Model Parameters'!$C$11*'Model Parameters'!$C$10) -> 1.1282365e-06 | H17: =B17*LN(G17) -> -27.38971 | I17: 0 | J17: =(I17+'Model Parameters'!$D$11)/('Model Parameters'!$D$9+'Model Parameters'!$D$11*'Model Parameters'!$D$10) -> 4.4086268e-06 | K17: =B17*LN(J17) -> -24.663895
A18: account_bank | B18: 1 | C18: 3 | D18: =(C18+'Model Parameters'!$B$11)/('Model Parameters'!$B$9+'Model Parameters'!$B$11*'Model Parameters'!$B$10) -> 3.4027986e-06 | E18: =B18*LN(D18) -> -12.590912 | F18: 0 | G18: =(F18+'Model Parameters'!$C$11)/('Model Parameters'!$C$9+'Model Parameters'!$C$11*'Model Parameters'!$C$10) -> 1.1282365e-06 | H18: =B18*LN(G18) -> -13.694855 | I18: 0 | J18: =(I18+'Model Parameters'!$D$11)/('Model Parameters'!$D$9+'Model Parameters'!$D$11*'Model Parameters'!$D$10) -> 4.4086268e-06 | K18: =B18*LN(J18) -> -12.331947
A19: account_closure | B19: 1 | C19: 308 | D19: =(C19+'Model Parameters'!$B$11)/('Model Parameters'!$B$9+'Model Parameters'!$B$11*'Model Parameters'!$B$10) -> 0.00026286619 | E19: =B19*LN(D19) -> -8.2438654 | F19: 0 | G19: =(F19+'Model Parameters'!$C$11)/('Model Parameters'!$C$9+'Model Parameters'!$C$11*'Model Parameters'!$C$10) -> 1.1282365e-06 | H19: =B19*LN(G19) -> -13.694855 | I19: 0 | J19: =(I19+'Model Parameters'!$D$11)/('Model Parameters'!$D$9+'Model Parameters'!$D$11*'Model Parameters'!$D$10) -> 4.4086268e-06 | K19: =B19*LN(J19) -> -12.331947
A20: account_shows | B20: 1 | C20: 18 | D20: =(C20+'Model Parameters'!$B$11)/('Model Parameters'!$B$9+'Model Parameters'!$B$11*'Model Parameters'!$B$10) -> 1.6163294e-05 | E20: =B20*LN(D20) -> -11.032768 | F20: 0 | G20: =(F20+'Model Parameters'!$C$11)/('Model Parameters'!$C$9+'Model Parameters'!$C$11*'Model Parameters'!$C$10) -> 1.1282365e-06 | H20: =B20*LN(G20) -> -13.694855 | I20: 0 | J20: =(I20+'Model Parameters'!$D$11)/('Model Parameters'!$D$9+'Model Parameters'!$D$11*'Model Parameters'!$D$10) -> 4.4086268e-06 | K20: =B20*LN(J20) -> -12.331947
... A74: within_hours | B74: 1 | C74: 1559 | D74: =(C74+'Model Parameters'!$B$11)/('Model Parameters'!$B$9+'Model Parameters'!$B$11*'Model Parameters'!$B$10) -> 0.0013270915 | E74: =B74*LN(D74) -> -6.6247656 | F74: 0 | G74: =(F74+'Model Parameters'!$C$11)/('Model Parameters'!$C$9+'Model Parameters'!$C$11*'Model Parameters'!$C$10) -> 1.1282365e-06 | H74: =B74*LN(G74) -> -13.694855 | I74: 0 | J74: =(I74+'Model Parameters'!$D$11)/('Model Parameters'!$D$9+'Model Parameters'!$D$11*'Model Parameters'!$D$10) -> 4.4086268e-06 | K74: =B74*LN(J74) -> -12.331947

Sheet Formula Calculations
A1: Formula Calculations
A2: Final scores and probabilities are Excel formulas linked to the other sheets.
A4: Calculation | B4: Fraud | C4: Injection | D4: Safe | E4: Formula shown
A5: Bayes theorem | E5: General: P(class | features) = [P(features | class) * P(class)] / P(features) Fraud: P(fraud | features) = [P(features | fraud) * P(fraud)] / P(features) Injection: P(injection | features) = [P(features | injection) * P(injection)] / P(features) Safe: P(safe | features) = [P(features | safe) * P(safe)] / P(features)
A6: Prior P(C_k) | B6: ='Model Parameters'!B7 -> 0.3333 | C6: ='Model Parameters'!C7 -> 0.3333 | D6: ='Model Parameters'!D7 -> 0.3334 | E6: P(fraud)=fraud_count/total_docs; P(injection)=injection_count/total_docs; P(safe)=safe_count/total_docs
A7: ln prior | B7: ='Model Parameters'!B8 -> -1.0987123 | C7: ='Model Parameters'!C8 -> -1.0987123 | D7: ='Model Parameters'!D8 -> -1.0984123 | E7: ln(P(fraud)), ln(P(injection)), ln(P(safe))
A8: Sum token log contributions | B8: =SUM('Token Table'!E7:E74) -> -728.963 | C8: =SUM('Token Table'!H7:H74) -> -1130.0448 | D8: =SUM('Token Table'!K7:K74) -> -1001.9764 | E8: sum_i count(token_i)*ln(P(token_i|fraud/injection/safe))
A9: Raw log score | B9: =B7+B8 -> -730.06172 | C9: =C7+C8 -> -1131.1435 | D9: =D7+D8 -> -1003.0749 | E9: log_score(fraud/injection/safe)=ln(P(class))+sum token log contributions
A10: Token count | B10: =SUM('Token Table'!B7:B74) -> 141 | C10: =B10 -> 141 | D10: =B10 -> 141 | E10: token_count = sum_i count(x_i)
A11: Calibrated logit | B11: =B9/B10 -> -5.1777427 | C11: =C9/C10 -> -8.0222945 | D11: =D9/D10 -> -7.1140061 | E11: logit(fraud/injection/safe)=raw_log_score(fraud/injection/safe)/token_count
A12: Max logit | B12: =MAX(B11:D11) -> -5.1777427 | C12: =B12 -> -5.1777427 | D12: =B12 -> -5.1777427 | E12: max_logit=max(logit(fraud),logit(injection),logit(safe))
A13: Exponentiated score | B13: =EXP((B11-B12)/'Model Parameters'!B12) -> 1 | C13: =EXP((C11-C12)/'Model Parameters'!C12) -> 6.6547877e-07 | D13: =EXP((D11-D12)/'Model Parameters'!D12) -> 6.2439215e-05 | E13: exp_score(class)=EXP((logit(class)-max_logit)/temperature)
A14: Final probability | B14: =B13/SUM($B$13:$D$13) -> 0.9999369 | C14: =C13/SUM($B$13:$D$13) -> 6.6543678e-07 | D14: =D13/SUM($B$13:$D$13) -> 6.2435275e-05 | E14: P(fraud|features), P(injection|features), P(safe|features) = each exp_score / total exp_scores
A16: Predicted label | B16: =INDEX($B$4:$D$4,1,MATCH(MAX(B9:D9),B9:D9,0)) -> Fraud | E16: predicted_label = class with maximum raw log score
A17: Status | B17: =IF(OR(B16="Fraud",B16="Injection"),"MALICIOUS","SAFE") -> MALICIOUS | E17: status = MALICIOUS when predicted label is fraud or injection, otherwise SAFE
